Workbook

Sheet Start Quote
B2: RENTAL QUOTE — START QUOTE
B3: Gas detection equipment rental. Enter quote & customer details. Yellow cells are inputs.
B5: LEGEND: | C5: Input | E5: Calculated
B7: QUOTE DETAILS
B8: Quote Number | E8: Rental Start Date
B9: Quote Date | E9: Rental End Date
B10: Valid Through | C10: =IF(AND(ISNUMBER(C9),ISNUMBER(F11)),C9+F11,"") | E10: Default Rental Days | F10: =IF(AND(ISNUMBER(F8),ISNUMBER(F9)),MAX(1,F9-F8+1),"")
B11: Salesperson | E11: Validity (days) | F11: 30
B13: CUSTOMER INFORMATION
B14: Customer / Company | E14: Phone
B15: Contact Name | E15: Project / Site
B16: Email
B18: CHARGES & TAX
B19: Tax Rate | C19: 0 | E19: Configured Equipment | F19: =Config_Subtotal -> 0
B20: Freight | C20: 0 | E20: Accessories & Services | F20: =Acc_Subtotal -> 0
B21: Miscellaneous Charge | C21: 0 | E21: Subtotal | F21: =Config_Subtotal+Acc_Subtotal -> 0
E22: Grand Total | F22: =F21+ROUND(F21*Tax_Rate,2)+Freight+Misc_Charge -> 0
B24: NOTES
B25: Customer Notes
B27: Internal Notes

Sheet Guided Configurator
B2: GUIDED CONFIGURATOR
B3: Configure up to 10 multi-gas units. Pick Device, then individually select LEL, O2, Toxic 1 and Toxic 2 sensors. Daily rate = base rental (USD List col C) + sensor upgrade surcharges. Yellow = input; grey = calculated.
B5: Legend: | C5: Input | D5: Calculated
B7: # | C7: Device | D7: LEL Sensor | E7: O2 | F7: Toxic 1 | G7: Toxic 2 | H7: Qty | I7: Days | J7: Disc % | K7: Base Daily | L7: Sensor Upg. Daily | M7: Unit Daily | N7: Extended Total | O7: Config Code | P7: Configuration Description | Q7: Status | R7: EXO 8-Gas Expansion Module | S7: Module Daily
B8: 1 | D8: LEL-IR | E8: O2 | F8: No Sensor | G8: No Sensor | H8: 1 | I8: =IF(ISNUMBER(Default_Days),Default_Days,1) -> 1 | J8: 0 | K8: =IF($C8="","",IFERROR(INDEX(DB_Rate,MATCH(IFERROR(INDEX(DeviceMap,MATCH($C8,INDEX(DeviceMap,0,1),0),2),""),DB_Key,0)),"?")) | L8: =IF($C8="","",IF(OR($D8="",$D8="No Sensor"),0,IF(IFERROR(INDEX(SensorTier,MATCH($D8,SensorName,0)),"Standard")="Standard",0,IFERROR(INDEX(DB_Rate,MATCH(IFERROR(INDEX(TierKeys,MATCH(IFERROR(INDEX(SensorTier,MATCH($D8,SensorName,0)),"Standard"),INDEX(TierKeys,0,1),0),2),""),DB_Key,0)),0)))+IF(OR($E8="",$E8="No Sensor"),0,IF(IFERROR(INDEX(SensorTier,MATCH($E8,SensorName,0)),"Standard")="Standard",0,IFERROR(INDEX(DB_Rate,MATCH(IFERROR(INDEX(TierKeys,MATCH(IFERROR(INDEX(SensorTier,MATCH($E8,SensorName,0)),"Standard"),INDEX(TierKeys,0,1),0),2),""),DB_Key,0)),0)))+IF(OR($F8="",$F8="No Sensor"),0,IF(IFERROR(INDEX(SensorTier,MATCH($F8,SensorName,0)),"Standard")="Standard",0,IFERROR(INDEX(DB_Rate,MATCH(IFERROR(INDEX(TierKeys,MATCH(IFERROR(INDEX(SensorTier,MATCH($F8,SensorName,0)),"Standard"),INDEX(TierKeys,0,1),0),2),""),DB_Key,0)),0)))+IF(OR($G8="",$G8="No Sensor"),0,IF(IFERROR(INDEX(SensorTier,MATCH($G8,SensorName,0)),"Standard")="Standard",0,IFERROR(INDEX(DB_Rate,MATCH(IFERROR(INDEX(TierKeys,MATCH(IFERROR(INDEX(SensorTier,MATCH($G8,SensorName,0)),"Standard"),INDEX(TierKeys,0,1),0),2),""),DB_Key,0)),0)))) | M8: =IF($C8="","",IF(ISNUMBER($K8),$K8+$L8+$S8,"")) | N8: =IF(AND($C8<>"",ISNUMBER($M8)),$H8*$I8*$M8*(1-$J8),0) -> 0 | O8: =IF($C8="","",SUBSTITUTE(IFERROR(INDEX(DeviceMap,MATCH($C8,INDEX(DeviceMap,0,1),0),3),""),"~",IF(OR($R8="",$R8="No Module"),"X",IFERROR(INDEX(GEMMap,MATCH($R8,INDEX(GEMMap,0,1),0),2),"X")))&"-"&$X8&"-1D") | P8: =IF($C8="","",$C8&", with ("&TEXTJOIN("/",TRUE,IF($D8="No Sensor","",$D8),IF($E8="No Sensor","",$E8),IF($F8="No Sensor","",$F8),IF($G8="No Sensor","",$G8))&")"&IF(OR($R8="",$R8="No Module"),""," + 8-gas expansion module: "&$R8)) | Q8: =IF($C8="","",IF(AND($R8<>"",$R8<>"No Module",ISERROR(SEARCH("EXO",$C8))),"Module needs EXO device",IF(OR($K8="?",NOT(ISNUMBER($M8))),"Unknown rate",IF(AND($F8<>"No Sensor",$F8=$G8),"Duplicate sensors",IF(AND($D8="No Sensor",$E8="No Sensor",$F8="No Sensor",$G8="No Sensor"),"Review: no sensors","Complete"))))) | R8: No Module | S8: =IF($C8="","",IF(OR($R8="",$R8="No Module"),0,IFERROR(INDEX(DB_Rate,MATCH(INDEX(GEMMap,MATCH($R8,INDEX(GEMMap,0,1),0),3),DB_Key,0)),0))) | T8: =CODE(IFERROR(INDEX(SensorCode,MATCH($D8,SensorName,0)),"X")) | U8: =CODE(IFERROR(INDEX(SensorCode,MATCH($E8,SensorName,0)),"X")) | V8: =CODE(IFERROR(INDEX(SensorCode,MATCH($F8,SensorName,0)),"X")) | W8: =CODE(IFERROR(INDEX(SensorCode,MATCH($G8,SensorName,0)),"X")) | X8: =CHAR(SMALL($T8:$W8,1))&CHAR(SMALL($T8:$W8,2))&CHAR(SMALL($T8:$W8,3))&CHAR(SMALL($T8:$W8,4))
B9: 2 | D9: LEL-IR | E9: O2 | F9: No Sensor | G9: No Sensor | H9: 1 | I9: =IF(ISNUMBER(Default_Days),Default_Days,1) -> 1 | J9: 0 | K9: =IF($C9="","",IFERROR(INDEX(DB_Rate,MATCH(IFERROR(INDEX(DeviceMap,MATCH($C9,INDEX(DeviceMap,0,1),0),2),""),DB_Key,0)),"?")) | L9: =IF($C9="","",IF(OR($D9="",$D9="No Sensor"),0,IF(IFERROR(INDEX(SensorTier,MATCH($D9,SensorName,0)),"Standard")="Standard",0,IFERROR(INDEX(DB_Rate,MATCH(IFERROR(INDEX(TierKeys,MATCH(IFERROR(INDEX(SensorTier,MATCH($D9,SensorName,0)),"Standard"),INDEX(TierKeys,0,1),0),2),""),DB_Key,0)),0)))+IF(OR($E9="",$E9="No Sensor"),0,IF(IFERROR(INDEX(SensorTier,MATCH($E9,SensorName,0)),"Standard")="Standard",0,IFERROR(INDEX(DB_Rate,MATCH(IFERROR(INDEX(TierKeys,MATCH(IFERROR(INDEX(SensorTier,MATCH($E9,SensorName,0)),"Standard"),INDEX(TierKeys,0,1),0),2),""),DB_Key,0)),0)))+IF(OR($F9="",$F9="No Sensor"),0,IF(IFERROR(INDEX(SensorTier,MATCH($F9,SensorName,0)),"Standard")="Standard",0,IFERROR(INDEX(DB_Rate,MATCH(IFERROR(INDEX(TierKeys,MATCH(IFERROR(INDEX(SensorTier,MATCH($F9,SensorName,0)),"Standard"),INDEX(TierKeys,0,1),0),2),""),DB_Key,0)),0)))+IF(OR($G9="",$G9="No Sensor"),0,IF(IFERROR(INDEX(SensorTier,MATCH($G9,SensorName,0)),"Standard")="Standard",0,IFERROR(INDEX(DB_Rate,MATCH(IFERROR(INDEX(TierKeys,MATCH(IFERROR(INDEX(SensorTier,MATCH($G9,SensorName,0)),"Standard"),INDEX(TierKeys,0,1),0),2),""),DB_Key,0)),0)))) | M9: =IF($C9="","",IF(ISNUMBER($K9),$K9+$L9+$S9,"")) | N9: =IF(AND($C9<>"",ISNUMBER($M9)),$H9*$I9*$M9*(1-$J9),0) -> 0 | O9: =IF($C9="","",SUBSTITUTE(IFERROR(INDEX(DeviceMap,MATCH($C9,INDEX(DeviceMap,0,1),0),3),""),"~",IF(OR($R9="",$R9="No Module"),"X",IFERROR(INDEX(GEMMap,MATCH($R9,INDEX(GEMMap,0,1),0),2),"X")))&"-"&$X9&"-1D") | P9: =IF($C9="","",$C9&", with ("&TEXTJOIN("/",TRUE,IF($D9="No Sensor","",$D9),IF($E9="No Sensor","",$E9),IF($F9="No Sensor","",$F9),IF($G9="No Sensor","",$G9))&")"&IF(OR($R9="",$R9="No Module"),""," + 8-gas expansion module: "&$R9)) | Q9: =IF($C9="","",IF(AND($R9<>"",$R9<>"No Module",ISERROR(SEARCH("EXO",$C9))),"Module needs EXO device",IF(OR($K9="?",NOT(ISNUMBER($M9))),"Unknown rate",IF(AND($F9<>"No Sensor",$F9=$G9),"Duplicate sensors",IF(AND($D9="No Sensor",$E9="No Sensor",$F9="No Sensor",$G9="No Sensor"),"Review: no sensors","Complete"))))) | R9: No Module | S9: =IF($C9="","",IF(OR($R9="",$R9="No Module"),0,IFERROR(INDEX(DB_Rate,MATCH(INDEX(GEMMap,MATCH($R9,INDEX(GEMMap,0,1),0),3),DB_Key,0)),0))) | T9: =CODE(IFERROR(INDEX(SensorCode,MATCH($D9,SensorName,0)),"X")) | U9: =CODE(IFERROR(INDEX(SensorCode,MATCH($E9,SensorName,0)),"X")) | V9: =CODE(IFERROR(INDEX(SensorCode,MATCH($F9,SensorName,0)),"X")) | W9: =CODE(IFERROR(INDEX(SensorCode,MATCH($G9,SensorName,0)),"X")) | X9: =CHAR(SMALL($T9:$W9,1))&CHAR(SMALL($T9:$W9,2))&CHAR(SMALL($T9:$W9,3))&CHAR(SMALL($T9:$W9,4))
B10: 3 | D10: LEL-IR | E10: O2 | F10: No Sensor | G10: No Sensor | H10: 1 | I10: =IF(ISNUMBER(Default_Days),Default_Days,1) -> 1 | J10: 0 | K10: =IF($C10="","",IFERROR(INDEX(DB_Rate,MATCH(IFERROR(INDEX(DeviceMap,MATCH($C10,INDEX(DeviceMap,0,1),0),2),""),DB_Key,0)),"?")) | L10: =IF($C10="","",IF(OR($D10="",$D10="No Sensor"),0,IF(IFERROR(INDEX(SensorTier,MATCH($D10,SensorName,0)),"Standard")="Standard",0,IFERROR(INDEX(DB_Rate,MATCH(IFERROR(INDEX(TierKeys,MATCH(IFERROR(INDEX(SensorTier,MATCH($D10,SensorName,0)),"Standard"),INDEX(TierKeys,0,1),0),2),""),DB_Key,0)),0)))+IF(OR($E10="",$E10="No Sensor"),0,IF(IFERROR(INDEX(SensorTier,MATCH($E10,SensorName,0)),"Standard")="Standard",0,IFERROR(INDEX(DB_Rate,MATCH(IFERROR(INDEX(TierKeys,MATCH(IFERROR(INDEX(SensorTier,MATCH($E10,SensorName,0)),"Standard"),INDEX(TierKeys,0,1),0),2),""),DB_Key,0)),0)))+IF(OR($F10="",$F10="No Sensor"),0,IF(IFERROR(INDEX(SensorTier,MATCH($F10,SensorName,0)),"Standard")="Standard",0,IFERROR(INDEX(DB_Rate,MATCH(IFERROR(INDEX(TierKeys,MATCH(IFERROR(INDEX(SensorTier,MATCH($F10,SensorName,0)),"Standard"),INDEX(TierKeys,0,1),0),2),""),DB_Key,0)),0)))+IF(OR($G10="",$G10="No Sensor"),0,IF(IFERROR(INDEX(SensorTier,MATCH($G10,SensorName,0)),"Standard")="Standard",0,IFERROR(INDEX(DB_Rate,MATCH(IFERROR(INDEX(TierKeys,MATCH(IFERROR(INDEX(SensorTier,MATCH($G10,SensorName,0)),"Standard"),INDEX(TierKeys,0,1),0),2),""),DB_Key,0)),0)))) | M10: =IF($C10="","",IF(ISNUMBER($K10),$K10+$L10+$S10,"")) | N10: =IF(AND($C10<>"",ISNUMBER($M10)),$H10*$I10*$M10*(1-$J10),0) -> 0 | O10: =IF($C10="","",SUBSTITUTE(IFERROR(INDEX(DeviceMap,MATCH($C10,INDEX(DeviceMap,0,1),0),3),""),"~",IF(OR($R10="",$R10="No Module"),"X",IFERROR(INDEX(GEMMap,MATCH($R10,INDEX(GEMMap,0,1),0),2),"X")))&"-"&$X10&"-1D") | P10: =IF($C10="","",$C10&", with ("&TEXTJOIN("/",TRUE,IF($D10="No Sensor","",$D10),IF($E10="No Sensor","",$E10),IF($F10="No Sensor","",$F10),IF($G10="No Sensor","",$G10))&")"&IF(OR($R10="",$R10="No Module"),""," + 8-gas expansion module: "&$R10)) | Q10: =IF($C10="","",IF(AND($R10<>"",$R10<>"No Module",ISERROR(SEARCH("EXO",$C10))),"Module needs EXO device",IF(OR($K10="?",NOT(ISNUMBER($M10))),"Unknown rate",IF(AND($F10<>"No Sensor",$F10=$G10),"Duplicate sensors",IF(AND($D10="No Sensor",$E10="No Sensor",$F10="No Sensor",$G10="No Sensor"),"Review: no sensors","Complete"))))) | R10: No Module | S10: =IF($C10="","",IF(OR($R10="",$R10="No Module"),0,IFERROR(INDEX(DB_Rate,MATCH(INDEX(GEMMap,MATCH($R10,INDEX(GEMMap,0,1),0),3),DB_Key,0)),0))) | T10: =CODE(IFERROR(INDEX(SensorCode,MATCH($D10,SensorName,0)),"X")) | U10: =CODE(IFERROR(INDEX(SensorCode,MATCH($E10,SensorName,0)),"X")) | V10: =CODE(IFERROR(INDEX(SensorCode,MATCH($F10,SensorName,0)),"X")) | W10: =CODE(IFERROR(INDEX(SensorCode,MATCH($G10,SensorName,0)),"X")) | X10: =CHAR(SMALL($T10:$W10,1))&CHAR(SMALL($T10:$W10,2))&CHAR(SMALL($T10:$W10,3))&CHAR(SMALL($T10:$W10,4))
B11: 4 | D11: LEL-IR | E11: O2 | F11: No Sensor | G11: No Sensor | H11: 1 | I11: =IF(ISNUMBER(Default_Days),Default_Days,1) -> 1 | J11: 0 | K11: =IF($C11="","",IFERROR(INDEX(DB_Rate,MATCH(IFERROR(INDEX(DeviceMap,MATCH($C11,INDEX(DeviceMap,0,1),0),2),""),DB_Key,0)),"?")) | L11: =IF($C11="","",IF(OR($D11="",$D11="No Sensor"),0,IF(IFERROR(INDEX(SensorTier,MATCH($D11,SensorName,0)),"Standard")="Standard",0,IFERROR(INDEX(DB_Rate,MATCH(IFERROR(INDEX(TierKeys,MATCH(IFERROR(INDEX(SensorTier,MATCH($D11,SensorName,0)),"Standard"),INDEX(TierKeys,0,1),0),2),""),DB_Key,0)),0)))+IF(OR($E11="",$E11="No Sensor"),0,IF(IFERROR(INDEX(SensorTier,MATCH($E11,SensorName,0)),"Standard")="Standard",0,IFERROR(INDEX(DB_Rate,MATCH(IFERROR(INDEX(TierKeys,MATCH(IFERROR(INDEX(SensorTier,MATCH($E11,SensorName,0)),"Standard"),INDEX(TierKeys,0,1),0),2),""),DB_Key,0)),0)))+IF(OR($F11="",$F11="No Sensor"),0,IF(IFERROR(INDEX(SensorTier,MATCH($F11,SensorName,0)),"Standard")="Standard",0,IFERROR(INDEX(DB_Rate,MATCH(IFERROR(INDEX(TierKeys,MATCH(IFERROR(INDEX(SensorTier,MATCH($F11,SensorName,0)),"Standard"),INDEX(TierKeys,0,1),0),2),""),DB_Key,0)),0)))+IF(OR($G11="",$G11="No Sensor"),0,IF(IFERROR(INDEX(SensorTier,MATCH($G11,SensorName,0)),"Standard")="Standard",0,IFERROR(INDEX(DB_Rate,MATCH(IFERROR(INDEX(TierKeys,MATCH(IFERROR(INDEX(SensorTier,MATCH($G11,SensorName,0)),"Standard"),INDEX(TierKeys,0,1),0),2),""),DB_Key,0)),0)))) | M11: =IF($C11="","",IF(ISNUMBER($K11),$K11+$L11+$S11,"")) | N11: =IF(AND($C11<>"",ISNUMBER($M11)),$H11*$I11*$M11*(1-$J11),0) -> 0 | O11: =IF($C11="","",SUBSTITUTE(IFERROR(INDEX(DeviceMap,MATCH($C11,INDEX(DeviceMap,0,1),0),3),""),"~",IF(OR($R11="",$R11="No Module"),"X",IFERROR(INDEX(GEMMap,MATCH($R11,INDEX(GEMMap,0,1),0),2),"X")))&"-"&$X11&"-1D") | P11: =IF($C11="","",$C11&", with ("&TEXTJOIN("/",TRUE,IF($D11="No Sensor","",$D11),IF($E11="No Sensor","",$E11),IF($F11="No Sensor","",$F11),IF($G11="No Sensor","",$G11))&")"&IF(OR($R11="",$R11="No Module"),""," + 8-gas expansion module: "&$R11)) | Q11: =IF($C11="","",IF(AND($R11<>"",$R11<>"No Module",ISERROR(SEARCH("EXO",$C11))),"Module needs EXO device",IF(OR($K11="?",NOT(ISNUMBER($M11))),"Unknown rate",IF(AND($F11<>"No Sensor",$F11=$G11),"Duplicate sensors",IF(AND($D11="No Sensor",$E11="No Sensor",$F11="No Sensor",$G11="No Sensor"),"Review: no sensors","Complete"))))) | R11: No Module | S11: =IF($C11="","",IF(OR($R11="",$R11="No Module"),0,IFERROR(INDEX(DB_Rate,MATCH(INDEX(GEMMap,MATCH($R11,INDEX(GEMMap,0,1),0),3),DB_Key,0)),0))) | T11: =CODE(IFERROR(INDEX(SensorCode,MATCH($D11,SensorName,0)),"X")) | U11: =CODE(IFERROR(INDEX(SensorCode,MATCH($E11,SensorName,0)),"X")) | V11: =CODE(IFERROR(INDEX(SensorCode,MATCH($F11,SensorName,0)),"X")) | W11: =CODE(IFERROR(INDEX(SensorCode,MATCH($G11,SensorName,0)),"X")) | X11: =CHAR(SMALL($T11:$W11,1))&CHAR(SMALL($T11:$W11,2))&CHAR(SMALL($T11:$W11,3))&CHAR(SMALL($T11:$W11,4))
B12: 5 | D12: LEL-IR | E12: O2 | F12: No Sensor | G12: No Sensor | H12: 1 | I12: =IF(ISNUMBER(Default_Days),Default_Days,1) -> 1 | J12: 0 | K12: =IF($C12="","",IFERROR(INDEX(DB_Rate,MATCH(IFERROR(INDEX(DeviceMap,MATCH($C12,INDEX(DeviceMap,0,1),0),2),""),DB_Key,0)),"?")) | L12: =IF($C12="","",IF(OR($D12="",$D12="No Sensor"),0,IF(IFERROR(INDEX(SensorTier,MATCH($D12,SensorName,0)),"Standard")="Standard",0,IFERROR(INDEX(DB_Rate,MATCH(IFERROR(INDEX(TierKeys,MATCH(IFERROR(INDEX(SensorTier,MATCH($D12,SensorName,0)),"Standard"),INDEX(TierKeys,0,1),0),2),""),DB_Key,0)),0)))+IF(OR($E12="",$E12="No Sensor"),0,IF(IFERROR(INDEX(SensorTier,MATCH($E12,SensorName,0)),"Standard")="Standard",0,IFERROR(INDEX(DB_Rate,MATCH(IFERROR(INDEX(TierKeys,MATCH(IFERROR(INDEX(SensorTier,MATCH($E12,SensorName,0)),"Standard"),INDEX(TierKeys,0,1),0),2),""),DB_Key,0)),0)))+IF(OR($F12="",$F12="No Sensor"),0,IF(IFERROR(INDEX(SensorTier,MATCH($F12,SensorName,0)),"Standard")="Standard",0,IFERROR(INDEX(DB_Rate,MATCH(IFERROR(INDEX(TierKeys,MATCH(IFERROR(INDEX(SensorTier,MATCH($F12,SensorName,0)),"Standard"),INDEX(TierKeys,0,1),0),2),""),DB_Key,0)),0)))+IF(OR($G12="",$G12="No Sensor"),0,IF(IFERROR(INDEX(SensorTier,MATCH($G12,SensorName,0)),"Standard")="Standard",0,IFERROR(INDEX(DB_Rate,MATCH(IFERROR(INDEX(TierKeys,MATCH(IFERROR(INDEX(SensorTier,MATCH($G12,SensorName,0)),"Standard"),INDEX(TierKeys,0,1),0),2),""),DB_Key,0)),0)))) | M12: =IF($C12="","",IF(ISNUMBER($K12),$K12+$L12+$S12,"")) | N12: =IF(AND($C12<>"",ISNUMBER($M12)),$H12*$I12*$M12*(1-$J12),0) -> 0 | O12: =IF($C12="","",SUBSTITUTE(IFERROR(INDEX(DeviceMap,MATCH($C12,INDEX(DeviceMap,0,1),0),3),""),"~",IF(OR($R12="",$R12="No Module"),"X",IFERROR(INDEX(GEMMap,MATCH($R12,INDEX(GEMMap,0,1),0),2),"X")))&"-"&$X12&"-1D") | P12: =IF($C12="","",$C12&", with ("&TEXTJOIN("/",TRUE,IF($D12="No Sensor","",$D12),IF($E12="No Sensor","",$E12),IF($F12="No Sensor","",$F12),IF($G12="No Sensor","",$G12))&")"&IF(OR($R12="",$R12="No Module"),""," + 8-gas expansion module: "&$R12)) | Q12: =IF($C12="","",IF(AND($R12<>"",$R12<>"No Module",ISERROR(SEARCH("EXO",$C12))),"Module needs EXO device",IF(OR($K12="?",NOT(ISNUMBER($M12))),"Unknown rate",IF(AND($F12<>"No Sensor",$F12=$G12),"Duplicate sensors",IF(AND($D12="No Sensor",$E12="No Sensor",$F12="No Sensor",$G12="No Sensor"),"Review: no sensors","Complete"))))) | R12: No Module | S12: =IF($C12="","",IF(OR($R12="",$R12="No Module"),0,IFERROR(INDEX(DB_Rate,MATCH(INDEX(GEMMap,MATCH($R12,INDEX(GEMMap,0,1),0),3),DB_Key,0)),0))) | T12: =CODE(IFERROR(INDEX(SensorCode,MATCH($D12,SensorName,0)),"X")) | U12: =CODE(IFERROR(INDEX(SensorCode,MATCH($E12,SensorName,0)),"X")) | V12: =CODE(IFERROR(INDEX(SensorCode,MATCH($F12,SensorName,0)),"X")) | W12: =CODE(IFERROR(INDEX(SensorCode,MATCH($G12,SensorName,0)),"X")) | X12: =CHAR(SMALL($T12:$W12,1))&CHAR(SMALL($T12:$W12,2))&CHAR(SMALL($T12:$W12,3))&CHAR(SMALL($T12:$W12,4))
B13: 6 | D13: LEL-IR | E13: O2 | F13: No Sensor | G13: No Sensor | H13: 1 | I13: =IF(ISNUMBER(Default_Days),Default_Days,1) -> 1 | J13: 0 | K13: =IF($C13="","",IFERROR(INDEX(DB_Rate,MATCH(IFERROR(INDEX(DeviceMap,MATCH($C13,INDEX(DeviceMap,0,1),0),2),""),DB_Key,0)),"?")) | L13: =IF($C13="","",IF(OR($D13="",$D13="No Sensor"),0,IF(IFERROR(INDEX(SensorTier,MATCH($D13,SensorName,0)),"Standard")="Standard",0,IFERROR(INDEX(DB_Rate,MATCH(IFERROR(INDEX(TierKeys,MATCH(IFERROR(INDEX(SensorTier,MATCH($D13,SensorName,0)),"Standard"),INDEX(TierKeys,0,1),0),2),""),DB_Key,0)),0)))+IF(OR($E13="",$E13="No Sensor"),0,IF(IFERROR(INDEX(SensorTier,MATCH($E13,SensorName,0)),"Standard")="Standard",0,IFERROR(INDEX(DB_Rate,MATCH(IFERROR(INDEX(TierKeys,MATCH(IFERROR(INDEX(SensorTier,MATCH($E13,SensorName,0)),"Standard"),INDEX(TierKeys,0,1),0),2),""),DB_Key,0)),0)))+IF(OR($F13="",$F13="No Sensor"),0,IF(IFERROR(INDEX(SensorTier,MATCH($F13,SensorName,0)),"Standard")="Standard",0,IFERROR(INDEX(DB_Rate,MATCH(IFERROR(INDEX(TierKeys,MATCH(IFERROR(INDEX(SensorTier,MATCH($F13,SensorName,0)),"Standard"),INDEX(TierKeys,0,1),0),2),""),DB_Key,0)),0)))+IF(OR($G13="",$G13="No Sensor"),0,IF(IFERROR(INDEX(SensorTier,MATCH($G13,SensorName,0)),"Standard")="Standard",0,IFERROR(INDEX(DB_Rate,MATCH(IFERROR(INDEX(TierKeys,MATCH(IFERROR(INDEX(SensorTier,MATCH($G13,SensorName,0)),"Standard"),INDEX(TierKeys,0,1),0),2),""),DB_Key,0)),0)))) | M13: =IF($C13="","",IF(ISNUMBER($K13),$K13+$L13+$S13,"")) | N13: =IF(AND($C13<>"",ISNUMBER($M13)),$H13*$I13*$M13*(1-$J13),0) -> 0 | O13: =IF($C13="","",SUBSTITUTE(IFERROR(INDEX(DeviceMap,MATCH($C13,INDEX(DeviceMap,0,1),0),3),""),"~",IF(OR($R13="",$R13="No Module"),"X",IFERROR(INDEX(GEMMap,MATCH($R13,INDEX(GEMMap,0,1),0),2),"X")))&"-"&$X13&"-1D") | P13: =IF($C13="","",$C13&", with ("&TEXTJOIN("/",TRUE,IF($D13="No Sensor","",$D13),IF($E13="No Sensor","",$E13),IF($F13="No Sensor","",$F13),IF($G13="No Sensor","",$G13))&")"&IF(OR($R13="",$R13="No Module"),""," + 8-gas expansion module: "&$R13)) | Q13: =IF($C13="","",IF(AND($R13<>"",$R13<>"No Module",ISERROR(SEARCH("EXO",$C13))),"Module needs EXO device",IF(OR($K13="?",NOT(ISNUMBER($M13))),"Unknown rate",IF(AND($F13<>"No Sensor",$F13=$G13),"Duplicate sensors",IF(AND($D13="No Sensor",$E13="No Sensor",$F13="No Sensor",$G13="No Sensor"),"Review: no sensors","Complete"))))) | R13: No Module | S13: =IF($C13="","",IF(OR($R13="",$R13="No Module"),0,IFERROR(INDEX(DB_Rate,MATCH(INDEX(GEMMap,MATCH($R13,INDEX(GEMMap,0,1),0),3),DB_Key,0)),0))) | T13: =CODE(IFERROR(INDEX(SensorCode,MATCH($D13,SensorName,0)),"X")) | U13: =CODE(IFERROR(INDEX(SensorCode,MATCH($E13,SensorName,0)),"X")) | V13: =CODE(IFERROR(INDEX(SensorCode,MATCH($F13,SensorName,0)),"X")) | W13: =CODE(IFERROR(INDEX(SensorCode,MATCH($G13,SensorName,0)),"X")) | X13: =CHAR(SMALL($T13:$W13,1))&CHAR(SMALL($T13:$W13,2))&CHAR(SMALL($T13:$W13,3))&CHAR(SMALL($T13:$W13,4))
B14: 7 | D14: LEL-IR | E14: O2 | F14: No Sensor | G14: No Sensor | H14: 1 | I14: =IF(ISNUMBER(Default_Days),Default_Days,1) -> 1 | J14: 0 | K14: =IF($C14="","",IFERROR(INDEX(DB_Rate,MATCH(IFERROR(INDEX(DeviceMap,MATCH($C14,INDEX(DeviceMap,0,1),0),2),""),DB_Key,0)),"?")) | L14: =IF($C14="","",IF(OR($D14="",$D14="No Sensor"),0,IF(IFERROR(INDEX(SensorTier,MATCH($D14,SensorName,0)),"Standard")="Standard",0,IFERROR(INDEX(DB_Rate,MATCH(IFERROR(INDEX(TierKeys,MATCH(IFERROR(INDEX(SensorTier,MATCH($D14,SensorName,0)),"Standard"),INDEX(TierKeys,0,1),0),2),""),DB_Key,0)),0)))+IF(OR($E14="",$E14="No Sensor"),0,IF(IFERROR(INDEX(SensorTier,MATCH($E14,SensorName,0)),"Standard")="Standard",0,IFERROR(INDEX(DB_Rate,MATCH(IFERROR(INDEX(TierKeys,MATCH(IFERROR(INDEX(SensorTier,MATCH($E14,SensorName,0)),"Standard"),INDEX(TierKeys,0,1),0),2),""),DB_Key,0)),0)))+IF(OR($F14="",$F14="No Sensor"),0,IF(IFERROR(INDEX(SensorTier,MATCH($F14,SensorName,0)),"Standard")="Standard",0,IFERROR(INDEX(DB_Rate,MATCH(IFERROR(INDEX(TierKeys,MATCH(IFERROR(INDEX(SensorTier,MATCH($F14,SensorName,0)),"Standard"),INDEX(TierKeys,0,1),0),2),""),DB_Key,0)),0)))+IF(OR($G14="",$G14="No Sensor"),0,IF(IFERROR(INDEX(SensorTier,MATCH($G14,SensorName,0)),"Standard")="Standard",0,IFERROR(INDEX(DB_Rate,MATCH(IFERROR(INDEX(TierKeys,MATCH(IFERROR(INDEX(SensorTier,MATCH($G14,SensorName,0)),"Standard"),INDEX(TierKeys,0,1),0),2),""),DB_Key,0)),0)))) | M14: =IF($C14="","",IF(ISNUMBER($K14),$K14+$L14+$S14,"")) | N14: =IF(AND($C14<>"",ISNUMBER($M14)),$H14*$I14*$M14*(1-$J14),0) -> 0 | O14: =IF($C14="","",SUBSTITUTE(IFERROR(INDEX(DeviceMap,MATCH($C14,INDEX(DeviceMap,0,1),0),3),""),"~",IF(OR($R14="",$R14="No Module"),"X",IFERROR(INDEX(GEMMap,MATCH($R14,INDEX(GEMMap,0,1),0),2),"X")))&"-"&$X14&"-1D") | P14: =IF($C14="","",$C14&", with ("&TEXTJOIN("/",TRUE,IF($D14="No Sensor","",$D14),IF($E14="No Sensor","",$E14),IF($F14="No Sensor","",$F14),IF($G14="No Sensor","",$G14))&")"&IF(OR($R14="",$R14="No Module"),""," + 8-gas expansion module: "&$R14)) | Q14: =IF($C14="","",IF(AND($R14<>"",$R14<>"No Module",ISERROR(SEARCH("EXO",$C14))),"Module needs EXO device",IF(OR($K14="?",NOT(ISNUMBER($M14))),"Unknown rate",IF(AND($F14<>"No Sensor",$F14=$G14),"Duplicate sensors",IF(AND($D14="No Sensor",$E14="No Sensor",$F14="No Sensor",$G14="No Sensor"),"Review: no sensors","Complete"))))) | R14: No Module | S14: =IF($C14="","",IF(OR($R14="",$R14="No Module"),0,IFERROR(INDEX(DB_Rate,MATCH(INDEX(GEMMap,MATCH($R14,INDEX(GEMMap,0,1),0),3),DB_Key,0)),0))) | T14: =CODE(IFERROR(INDEX(SensorCode,MATCH($D14,SensorName,0)),"X")) | U14: =CODE(IFERROR(INDEX(SensorCode,MATCH($E14,SensorName,0)),"X")) | V14: =CODE(IFERROR(INDEX(SensorCode,MATCH($F14,SensorName,0)),"X")) | W14: =CODE(IFERROR(INDEX(SensorCode,MATCH($G14,SensorName,0)),"X")) | X14: =CHAR(SMALL($T14:$W14,1))&CHAR(SMALL($T14:$W14,2))&CHAR(SMALL($T14:$W14,3))&CHAR(SMALL($T14:$W14,4))
B15: 8 | D15: LEL-IR | E15: O2 | F15: No Sensor | G15: No Sensor | H15: 1 | I15: =IF(ISNUMBER(Default_Days),Default_Days,1) -> 1 | J15: 0 | K15: =IF($C15="","",IFERROR(INDEX(DB_Rate,MATCH(IFERROR(INDEX(DeviceMap,MATCH($C15,INDEX(DeviceMap,0,1),0),2),""),DB_Key,0)),"?")) | L15: =IF($C15="","",IF(OR($D15="",$D15="No Sensor"),0,IF(IFERROR(INDEX(SensorTier,MATCH($D15,SensorName,0)),"Standard")="Standard",0,IFERROR(INDEX(DB_Rate,MATCH(IFERROR(INDEX(TierKeys,MATCH(IFERROR(INDEX(SensorTier,MATCH($D15,SensorName,0)),"Standard"),INDEX(TierKeys,0,1),0),2),""),DB_Key,0)),0)))+IF(OR($E15="",$E15="No Sensor"),0,IF(IFERROR(INDEX(SensorTier,MATCH($E15,SensorName,0)),"Standard")="Standard",0,IFERROR(INDEX(DB_Rate,MATCH(IFERROR(INDEX(TierKeys,MATCH(IFERROR(INDEX(SensorTier,MATCH($E15,SensorName,0)),"Standard"),INDEX(TierKeys,0,1),0),2),""),DB_Key,0)),0)))+IF(OR($F15="",$F15="No Sensor"),0,IF(IFERROR(INDEX(SensorTier,MATCH($F15,SensorName,0)),"Standard")="Standard",0,IFERROR(INDEX(DB_Rate,MATCH(IFERROR(INDEX(TierKeys,MATCH(IFERROR(INDEX(SensorTier,MATCH($F15,SensorName,0)),"Standard"),INDEX(TierKeys,0,1),0),2),""),DB_Key,0)),0)))+IF(OR($G15="",$G15="No Sensor"),0,IF(IFERROR(INDEX(SensorTier,MATCH($G15,SensorName,0)),"Standard")="Standard",0,IFERROR(INDEX(DB_Rate,MATCH(IFERROR(INDEX(TierKeys,MATCH(IFERROR(INDEX(SensorTier,MATCH($G15,SensorName,0)),"Standard"),INDEX(TierKeys,0,1),0),2),""),DB_Key,0)),0)))) | M15: =IF($C15="","",IF(ISNUMBER($K15),$K15+$L15+$S15,"")) | N15: =IF(AND($C15<>"",ISNUMBER($M15)),$H15*$I15*$M15*(1-$J15),0) -> 0 | O15: =IF($C15="","",SUBSTITUTE(IFERROR(INDEX(DeviceMap,MATCH($C15,INDEX(DeviceMap,0,1),0),3),""),"~",IF(OR($R15="",$R15="No Module"),"X",IFERROR(INDEX(GEMMap,MATCH($R15,INDEX(GEMMap,0,1),0),2),"X")))&"-"&$X15&"-1D") | P15: =IF($C15="","",$C15&", with ("&TEXTJOIN("/",TRUE,IF($D15="No Sensor","",$D15),IF($E15="No Sensor","",$E15),IF($F15="No Sensor","",$F15),IF($G15="No Sensor","",$G15))&")"&IF(OR($R15="",$R15="No Module"),""," + 8-gas expansion module: "&$R15)) | Q15: =IF($C15="","",IF(AND($R15<>"",$R15<>"No Module",ISERROR(SEARCH("EXO",$C15))),"Module needs EXO device",IF(OR($K15="?",NOT(ISNUMBER($M15))),"Unknown rate",IF(AND($F15<>"No Sensor",$F15=$G15),"Duplicate sensors",IF(AND($D15="No Sensor",$E15="No Sensor",$F15="No Sensor",$G15="No Sensor"),"Review: no sensors","Complete"))))) | R15: No Module | S15: =IF($C15="","",IF(OR($R15="",$R15="No Module"),0,IFERROR(INDEX(DB_Rate,MATCH(INDEX(GEMMap,MATCH($R15,INDEX(GEMMap,0,1),0),3),DB_Key,0)),0))) | T15: =CODE(IFERROR(INDEX(SensorCode,MATCH($D15,SensorName,0)),"X")) | U15: =CODE(IFERROR(INDEX(SensorCode,MATCH($E15,SensorName,0)),"X")) | V15: =CODE(IFERROR(INDEX(SensorCode,MATCH($F15,SensorName,0)),"X")) | W15: =CODE(IFERROR(INDEX(SensorCode,MATCH($G15,SensorName,0)),"X")) | X15: =CHAR(SMALL($T15:$W15,1))&CHAR(SMALL($T15:$W15,2))&CHAR(SMALL($T15:$W15,3))&CHAR(SMALL($T15:$W15,4))
B16: 9 | D16: LEL-IR | E16: O2 | F16: No Sensor | G16: No Sensor | H16: 1 | I16: =IF(ISNUMBER(Default_Days),Default_Days,1) -> 1 | J16: 0 | K16: =IF($C16="","",IFERROR(INDEX(DB_Rate,MATCH(IFERROR(INDEX(DeviceMap,MATCH($C16,INDEX(DeviceMap,0,1),0),2),""),DB_Key,0)),"?")) | L16: =IF($C16="","",IF(OR($D16="",$D16="No Sensor"),0,IF(IFERROR(INDEX(SensorTier,MATCH($D16,SensorName,0)),"Standard")="Standard",0,IFERROR(INDEX(DB_Rate,MATCH(IFERROR(INDEX(TierKeys,MATCH(IFERROR(INDEX(SensorTier,MATCH($D16,SensorName,0)),"Standard"),INDEX(TierKeys,0,1),0),2),""),DB_Key,0)),0)))+IF(OR($E16="",$E16="No Sensor"),0,IF(IFERROR(INDEX(SensorTier,MATCH($E16,SensorName,0)),"Standard")="Standard",0,IFERROR(INDEX(DB_Rate,MATCH(IFERROR(INDEX(TierKeys,MATCH(IFERROR(INDEX(SensorTier,MATCH($E16,SensorName,0)),"Standard"),INDEX(TierKeys,0,1),0),2),""),DB_Key,0)),0)))+IF(OR($F16="",$F16="No Sensor"),0,IF(IFERROR(INDEX(SensorTier,MATCH($F16,SensorName,0)),"Standard")="Standard",0,IFERROR(INDEX(DB_Rate,MATCH(IFERROR(INDEX(TierKeys,MATCH(IFERROR(INDEX(SensorTier,MATCH($F16,SensorName,0)),"Standard"),INDEX(TierKeys,0,1),0),2),""),DB_Key,0)),0)))+IF(OR($G16="",$G16="No Sensor"),0,IF(IFERROR(INDEX(SensorTier,MATCH($G16,SensorName,0)),"Standard")="Standard",0,IFERROR(INDEX(DB_Rate,MATCH(IFERROR(INDEX(TierKeys,MATCH(IFERROR(INDEX(SensorTier,MATCH($G16,SensorName,0)),"Standard"),INDEX(TierKeys,0,1),0),2),""),DB_Key,0)),0)))) | M16: =IF($C16="","",IF(ISNUMBER($K16),$K16+$L16+$S16,"")) | N16: =IF(AND($C16<>"",ISNUMBER($M16)),$H16*$I16*$M16*(1-$J16),0) -> 0 | O16: =IF($C16="","",SUBSTITUTE(IFERROR(INDEX(DeviceMap,MATCH($C16,INDEX(DeviceMap,0,1),0),3),""),"~",IF(OR($R16="",$R16="No Module"),"X",IFERROR(INDEX(GEMMap,MATCH($R16,INDEX(GEMMap,0,1),0),2),"X")))&"-"&$X16&"-1D") | P16: =IF($C16="","",$C16&", with ("&TEXTJOIN("/",TRUE,IF($D16="No Sensor","",$D16),IF($E16="No Sensor","",$E16),IF($F16="No Sensor","",$F16),IF($G16="No Sensor","",$G16))&")"&IF(OR($R16="",$R16="No Module"),""," + 8-gas expansion module: "&$R16)) | Q16: =IF($C16="","",IF(AND($R16<>"",$R16<>"No Module",ISERROR(SEARCH("EXO",$C16))),"Module needs EXO device",IF(OR($K16="?",NOT(ISNUMBER($M16))),"Unknown rate",IF(AND($F16<>"No Sensor",$F16=$G16),"Duplicate sensors",IF(AND($D16="No Sensor",$E16="No Sensor",$F16="No Sensor",$G16="No Sensor"),"Review: no sensors","Complete"))))) | R16: No Module | S16: =IF($C16="","",IF(OR($R16="",$R16="No Module"),0,IFERROR(INDEX(DB_Rate,MATCH(INDEX(GEMMap,MATCH($R16,INDEX(GEMMap,0,1),0),3),DB_Key,0)),0))) | T16: =CODE(IFERROR(INDEX(SensorCode,MATCH($D16,SensorName,0)),"X")) | U16: =CODE(IFERROR(INDEX(SensorCode,MATCH($E16,SensorName,0)),"X")) | V16: =CODE(IFERROR(INDEX(SensorCode,MATCH($F16,SensorName,0)),"X")) | W16: =CODE(IFERROR(INDEX(SensorCode,MATCH($G16,SensorName,0)),"X")) | X16: =CHAR(SMALL($T16:$W16,1))&CHAR(SMALL($T16:$W16,2))&CHAR(SMALL($T16:$W16,3))&CHAR(SMALL($T16:$W16,4))
B17: 10 | D17: LEL-IR | E17: O2 | F17: No Sensor | G17: No Sensor | H17: 1 | I17: =IF(ISNUMBER(Default_Days),Default_Days,1) -> 1 | J17: 0 | K17: =IF($C17="","",IFERROR(INDEX(DB_Rate,MATCH(IFERROR(INDEX(DeviceMap,MATCH($C17,INDEX(DeviceMap,0,1),0),2),""),DB_Key,0)),"?")) | L17: =IF($C17="","",IF(OR($D17="",$D17="No Sensor"),0,IF(IFERROR(INDEX(SensorTier,MATCH($D17,SensorName,0)),"Standard")="Standard",0,IFERROR(INDEX(DB_Rate,MATCH(IFERROR(INDEX(TierKeys,MATCH(IFERROR(INDEX(SensorTier,MATCH($D17,SensorName,0)),"Standard"),INDEX(TierKeys,0,1),0),2),""),DB_Key,0)),0)))+IF(OR($E17="",$E17="No Sensor"),0,IF(IFERROR(INDEX(SensorTier,MATCH($E17,SensorName,0)),"Standard")="Standard",0,IFERROR(INDEX(DB_Rate,MATCH(IFERROR(INDEX(TierKeys,MATCH(IFERROR(INDEX(SensorTier,MATCH($E17,SensorName,0)),"Standard"),INDEX(TierKeys,0,1),0),2),""),DB_Key,0)),0)))+IF(OR($F17="",$F17="No Sensor"),0,IF(IFERROR(INDEX(SensorTier,MATCH($F17,SensorName,0)),"Standard")="Standard",0,IFERROR(INDEX(DB_Rate,MATCH(IFERROR(INDEX(TierKeys,MATCH(IFERROR(INDEX(SensorTier,MATCH($F17,SensorName,0)),"Standard"),INDEX(TierKeys,0,1),0),2),""),DB_Key,0)),0)))+IF(OR($G17="",$G17="No Sensor"),0,IF(IFERROR(INDEX(SensorTier,MATCH($G17,SensorName,0)),"Standard")="Standard",0,IFERROR(INDEX(DB_Rate,MATCH(IFERROR(INDEX(TierKeys,MATCH(IFERROR(INDEX(SensorTier,MATCH($G17,SensorName,0)),"Standard"),INDEX(TierKeys,0,1),0),2),""),DB_Key,0)),0)))) | M17: =IF($C17="","",IF(ISNUMBER($K17),$K17+$L17+$S17,"")) | N17: =IF(AND($C17<>"",ISNUMBER($M17)),$H17*$I17*$M17*(1-$J17),0) -> 0 | O17: =IF($C17="","",SUBSTITUTE(IFERROR(INDEX(DeviceMap,MATCH($C17,INDEX(DeviceMap,0,1),0),3),""),"~",IF(OR($R17="",$R17="No Module"),"X",IFERROR(INDEX(GEMMap,MATCH($R17,INDEX(GEMMap,0,1),0),2),"X")))&"-"&$X17&"-1D") | P17: =IF($C17="","",$C17&", with ("&TEXTJOIN("/",TRUE,IF($D17="No Sensor","",$D17),IF($E17="No Sensor","",$E17),IF($F17="No Sensor","",$F17),IF($G17="No Sensor","",$G17))&")"&IF(OR($R17="",$R17="No Module"),""," + 8-gas expansion module: "&$R17)) | Q17: =IF($C17="","",IF(AND($R17<>"",$R17<>"No Module",ISERROR(SEARCH("EXO",$C17))),"Module needs EXO device",IF(OR($K17="?",NOT(ISNUMBER($M17))),"Unknown rate",IF(AND($F17<>"No Sensor",$F17=$G17),"Duplicate sensors",IF(AND($D17="No Sensor",$E17="No Sensor",$F17="No Sensor",$G17="No Sensor"),"Review: no sensors","Complete"))))) | R17: No Module | S17: =IF($C17="","",IF(OR($R17="",$R17="No Module"),0,IFERROR(INDEX(DB_Rate,MATCH(INDEX(GEMMap,MATCH($R17,INDEX(GEMMap,0,1),0),3),DB_Key,0)),0))) | T17: =CODE(IFERROR(INDEX(SensorCode,MATCH($D17,SensorName,0)),"X")) | U17: =CODE(IFERROR(INDEX(SensorCode,MATCH($E17,SensorName,0)),"X")) | V17: =CODE(IFERROR(INDEX(SensorCode,MATCH($F17,SensorName,0)),"X")) | W17: =CODE(IFERROR(INDEX(SensorCode,MATCH($G17,SensorName,0)),"X")) | X17: =CHAR(SMALL($T17:$W17,1))&CHAR(SMALL($T17:$W17,2))&CHAR(SMALL($T17:$W17,3))&CHAR(SMALL($T17:$W17,4))
M19: Configured Equipment Subtotal | N19: =SUM(N8:N17) -> 0

Sheet Accessories & Services
B2: ACCESSORIES & SERVICES
B3: Add G7/EXO accessories, bridges, services, monitoring, consumables, calibration gas and training. All rates from USD List column C. Choose Daily or One-Time. Use Rate Override for blank/manual-rate lines.
B5: Include | C5: SKU | D5: Description | E5: Category | F5: Method | G5: Qty | H5: Days | I5: Daily Rate | J5: Rate Override | K5: Eff. Rate | L5: Disc % | M5: Extended | N5: Notes
B6: No | C6: RENT-BEACON | D6: =IF($C6="","",IFERROR(INDEX(DB_Desc,MATCH($C6,DB_Key,0)),"** SKU not found **")) -> Rental service, beacon, daily rate | E6: =IF($C6="","",IFERROR(INDEX(DB_Cat,MATCH($C6,DB_Key,0)),"")) -> G7 Accessories | F6: Daily | G6: 1 | H6: =IF(ISNUMBER(Default_Days),Default_Days,1) -> 1 | I6: =IF($C6="","",IFERROR(INDEX(DB_Rate,MATCH($C6,DB_Key,0)),"")) -> 2.4 | K6: =IF($C6="","",IF(ISNUMBER($J6),$J6,IF(ISNUMBER($I6),$I6,""))) -> 2.4 | L6: 0 | M6: =IF(AND($B6="Yes",$C6<>"",ISNUMBER($K6)),IF($F6="One-Time",$G6*$K6*(1-$L6),$G6*$H6*$K6*(1-$L6)),0) -> 0
B7: No | C7: RENT-TRAIN | D7: =IF($C7="","",IFERROR(INDEX(DB_Desc,MATCH($C7,DB_Key,0)),"** SKU not found **")) -> Training, Daily, at Blackline Facility | E7: =IF($C7="","",IFERROR(INDEX(DB_Cat,MATCH($C7,DB_Key,0)),"")) -> Additional Services | F7: Daily | G7: 1 | H7: =IF(ISNUMBER(Default_Days),Default_Days,1) -> 1 | I7: =IF($C7="","",IFERROR(INDEX(DB_Rate,MATCH($C7,DB_Key,0)),"")) -> 1000 | K7: =IF($C7="","",IF(ISNUMBER($J7),$J7,IF(ISNUMBER($I7),$I7,""))) -> 1000 | L7: 0 | M7: =IF(AND($B7="Yes",$C7<>"",ISNUMBER($K7)),IF($F7="One-Time",$G7*$K7*(1-$L7),$G7*$H7*$K7*(1-$L7)),0) -> 0
B8: No | C8: RENTAL-ONE-TIME | D8: =IF($C8="","",IFERROR(INDEX(DB_Desc,MATCH($C8,DB_Key,0)),"** SKU not found **")) -> One time charge - as needed [MANUAL PRICE REQUIRED] | E8: =IF($C8="","",IFERROR(INDEX(DB_Cat,MATCH($C8,DB_Key,0)),"")) -> Additional Services | F8: Daily | G8: 1 | H8: =IF(ISNUMBER(Default_Days),Default_Days,1) -> 1 | I8: =IF($C8="","",IFERROR(INDEX(DB_Rate,MATCH($C8,DB_Key,0)),"")) -> 0 | J8: 300 | K8: =IF($C8="","",IF(ISNUMBER($J8),$J8,IF(ISNUMBER($I8),$I8,""))) -> 300 | L8: 0 | M8: =IF(AND($B8="Yes",$C8<>"",ISNUMBER($K8)),IF($F8="One-Time",$G8*$K8*(1-$L8),$G8*$H8*$K8*(1-$L8)),0) -> 0
B9: No | D9: =IF($C9="","",IFERROR(INDEX(DB_Desc,MATCH($C9,DB_Key,0)),"** SKU not found **")) | E9: =IF($C9="","",IFERROR(INDEX(DB_Cat,MATCH($C9,DB_Key,0)),"")) | F9: Daily | G9: 1 | H9: =IF(ISNUMBER(Default_Days),Default_Days,1) -> 1 | I9: =IF($C9="","",IFERROR(INDEX(DB_Rate,MATCH($C9,DB_Key,0)),"")) | K9: =IF($C9="","",IF(ISNUMBER($J9),$J9,IF(ISNUMBER($I9),$I9,""))) | L9: 0 | M9: =IF(AND($B9="Yes",$C9<>"",ISNUMBER($K9)),IF($F9="One-Time",$G9*$K9*(1-$L9),$G9*$H9*$K9*(1-$L9)),0) -> 0
B10: No | D10: =IF($C10="","",IFERROR(INDEX(DB_Desc,MATCH($C10,DB_Key,0)),"** SKU not found **")) | E10: =IF($C10="","",IFERROR(INDEX(DB_Cat,MATCH($C10,DB_Key,0)),"")) | F10: Daily | G10: 1 | H10: =IF(ISNUMBER(Default_Days),Default_Days,1) -> 1 | I10: =IF($C10="","",IFERROR(INDEX(DB_Rate,MATCH($C10,DB_Key,0)),"")) | K10: =IF($C10="","",IF(ISNUMBER($J10),$J10,IF(ISNUMBER($I10),$I10,""))) | L10: 0 | M10: =IF(AND($B10="Yes",$C10<>"",ISNUMBER($K10)),IF($F10="One-Time",$G10*$K10*(1-$L10),$G10*$H10*$K10*(1-$L10)),0) -> 0
B11: No | D11: =IF($C11="","",IFERROR(INDEX(DB_Desc,MATCH($C11,DB_Key,0)),"** SKU not found **")) | E11: =IF($C11="","",IFERROR(INDEX(DB_Cat,MATCH($C11,DB_Key,0)),"")) | F11: Daily | G11: 1 | H11: =IF(ISNUMBER(Default_Days),Default_Days,1) -> 1 | I11: =IF($C11="","",IFERROR(INDEX(DB_Rate,MATCH($C11,DB_Key,0)),"")) | K11: =IF($C11="","",IF(ISNUMBER($J11),$J11,IF(ISNUMBER($I11),$I11,""))) | L11: 0 | M11: =IF(AND($B11="Yes",$C11<>"",ISNUMBER($K11)),IF($F11="One-Time",$G11*$K11*(1-$L11),$G11*$H11*$K11*(1-$L11)),0) -> 0
B12: No | D12: =IF($C12="","",IFERROR(INDEX(DB_Desc,MATCH($C12,DB_Key,0)),"** SKU not found **")) | E12: =IF($C12="","",IFERROR(INDEX(DB_Cat,MATCH($C12,DB_Key,0)),"")) | F12: Daily | G12: 1 | H12: =IF(ISNUMBER(Default_Days),Default_Days,1) -> 1 | I12: =IF($C12="","",IFERROR(INDEX(DB_Rate,MATCH($C12,DB_Key,0)),"")) | K12: =IF($C12="","",IF(ISNUMBER($J12),$J12,IF(ISNUMBER($I12),$I12,""))) | L12: 0 | M12: =IF(AND($B12="Yes",$C12<>"",ISNUMBER($K12)),IF($F12="One-Time",$G12*$K12*(1-$L12),$G12*$H12*$K12*(1-$L12)),0) -> 0
B13: No | D13: =IF($C13="","",IFERROR(INDEX(DB_Desc,MATCH($C13,DB_Key,0)),"** SKU not found **")) | E13: =IF($C13="","",IFERROR(INDEX(DB_Cat,MATCH($C13,DB_Key,0)),"")) | F13: Daily | G13: 1 | H13: =IF(ISNUMBER(Default_Days),Default_Days,1) -> 1 | I13: =IF($C13="","",IFERROR(INDEX(DB_Rate,MATCH($C13,DB_Key,0)),"")) | K13: =IF($C13="","",IF(ISNUMBER($J13),$J13,IF(ISNUMBER($I13),$I13,""))) | L13: 0 | M13: =IF(AND($B13="Yes",$C13<>"",ISNUMBER($K13)),IF($F13="One-Time",$G13*$K13*(1-$L13),$G13*$H13*$K13*(1-$L13)),0) -> 0
B14: No | D14: =IF($C14="","",IFERROR(INDEX(DB_Desc,MATCH($C14,DB_Key,0)),"** SKU not found **")) | E14: =IF($C14="","",IFERROR(INDEX(DB_Cat,MATCH($C14,DB_Key,0)),"")) | F14: Daily | G14: 1 | H14: =IF(ISNUMBER(Default_Days),Default_Days,1) -> 1 | I14: =IF($C14="","",IFERROR(INDEX(DB_Rate,MATCH($C14,DB_Key,0)),"")) | K14: =IF($C14="","",IF(ISNUMBER($J14),$J14,IF(ISNUMBER($I14),$I14,""))) | L14: 0 | M14: =IF(AND($B14="Yes",$C14<>"",ISNUMBER($K14)),IF($F14="One-Time",$G14*$K14*(1-$L14),$G14*$H14*$K14*(1-$L14)),0) -> 0
B15: No | D15: =IF($C15="","",IFERROR(INDEX(DB_Desc,MATCH($C15,DB_Key,0)),"** SKU not found **")) | E15: =IF($C15="","",IFERROR(INDEX(DB_Cat,MATCH($C15,DB_Key,0)),"")) | F15: Daily | G15: 1 | H15: =IF(ISNUMBER(Default_Days),Default_Days,1) -> 1 | I15: =IF($C15="","",IFERROR(INDEX(DB_Rate,MATCH($C15,DB_Key,0)),"")) | K15: =IF($C15="","",IF(ISNUMBER($J15),$J15,IF(ISNUMBER($I15),$I15,""))) | L15: 0 | M15: =IF(AND($B15="Yes",$C15<>"",ISNUMBER($K15)),IF($F15="One-Time",$G15*$K15*(1-$L15),$G15*$H15*$K15*(1-$L15)),0) -> 0
B16: No | D16: =IF($C16="","",IFERROR(INDEX(DB_Desc,MATCH($C16,DB_Key,0)),"** SKU not found **")) | E16: =IF($C16="","",IFERROR(INDEX(DB_Cat,MATCH($C16,DB_Key,0)),"")) | F16: Daily | G16: 1 | H16: =IF(ISNUMBER(Default_Days),Default_Days,1) -> 1 | I16: =IF($C16="","",IFERROR(INDEX(DB_Rate,MATCH($C16,DB_Key,0)),"")) | K16: =IF($C16="","",IF(ISNUMBER($J16),$J16,IF(ISNUMBER($I16),$I16,""))) | L16: 0 | M16: =IF(AND($B16="Yes",$C16<>"",ISNUMBER($K16)),IF($F16="One-Time",$G16*$K16*(1-$L16),$G16*$H16*$K16*(1-$L16)),0) -> 0
B17: No | D17: =IF($C17="","",IFERROR(INDEX(DB_Desc,MATCH($C17,DB_Key,0)),"** SKU not found **")) | E17: =IF($C17="","",IFERROR(INDEX(DB_Cat,MATCH($C17,DB_Key,0)),"")) | F17: Daily | G17: 1 | H17: =IF(ISNUMBER(Default_Days),Default_Days,1) -> 1 | I17: =IF($C17="","",IFERROR(INDEX(DB_Rate,MATCH($C17,DB_Key,0)),"")) | K17: =IF($C17="","",IF(ISNUMBER($J17),$J17,IF(ISNUMBER($I17),$I17,""))) | L17: 0 | M17: =IF(AND($B17="Yes",$C17<>"",ISNUMBER($K17)),IF($F17="One-Time",$G17*$K17*(1-$L17),$G17*$H17*$K17*(1-$L17)),0) -> 0
B18: No | D18: =IF($C18="","",IFERROR(INDEX(DB_Desc,MATCH($C18,DB_Key,0)),"** SKU not found **")) | E18: =IF($C18="","",IFERROR(INDEX(DB_Cat,MATCH($C18,DB_Key,0)),"")) | F18: Daily | G18: 1 | H18: =IF(ISNUMBER(Default_Days),Default_Days,1) -> 1 | I18: =IF($C18="","",IFERROR(INDEX(DB_Rate,MATCH($C18,DB_Key,0)),"")) | K18: =IF($C18="","",IF(ISNUMBER($J18),$J18,IF(ISNUMBER($I18),$I18,""))) | L18: 0 | M18: =IF(AND($B18="Yes",$C18<>"",ISNUMBER($K18)),IF($F18="One-Time",$G18*$K18*(1-$L18),$G18*$H18*$K18*(1-$L18)),0) -> 0
B19: No | D19: =IF($C19="","",IFERROR(INDEX(DB_Desc,MATCH($C19,DB_Key,0)),"** SKU not found **")) | E19: =IF($C19="","",IFERROR(INDEX(DB_Cat,MATCH($C19,DB_Key,0)),"")) | F19: Daily | G19: 1 | H19: =IF(ISNUMBER(Default_Days),Default_Days,1) -> 1 | I19: =IF($C19="","",IFERROR(INDEX(DB_Rate,MATCH($C19,DB_Key,0)),"")) | K19: =IF($C19="","",IF(ISNUMBER($J19),$J19,IF(ISNUMBER($I19),$I19,""))) | L19: 0 | M19: =IF(AND($B19="Yes",$C19<>"",ISNUMBER($K19)),IF($F19="One-Time",$G19*$K19*(1-$L19),$G19*$H19*$K19*(1-$L19)),0) -> 0
B20: No | D20: =IF($C20="","",IFERROR(INDEX(DB_Desc,MATCH($C20,DB_Key,0)),"** SKU not found **")) | E20: =IF($C20="","",IFERROR(INDEX(DB_Cat,MATCH($C20,DB_Key,0)),"")) | F20: Daily | G20: 1 | H20: =IF(ISNUMBER(Default_Days),Default_Days,1) -> 1 | I20: =IF($C20="","",IFERROR(INDEX(DB_Rate,MATCH($C20,DB_Key,0)),"")) | K20: =IF($C20="","",IF(ISNUMBER($J20),$J20,IF(ISNUMBER($I20),$I20,""))) | L20: 0 | M20: =IF(AND($B20="Yes",$C20<>"",ISNUMBER($K20)),IF($F20="One-Time",$G20*$K20*(1-$L20),$G20*$H20*$K20*(1-$L20)),0) -> 0
... B33: No | D33: =IF($C33="","",IFERROR(INDEX(DB_Desc,MATCH($C33,DB_Key,0)),"** SKU not found **")) | E33: =IF($C33="","",IFERROR(INDEX(DB_Cat,MATCH($C33,DB_Key,0)),"")) | F33: Daily | G33: 1 | H33: =IF(ISNUMBER(Default_Days),Default_Days,1) -> 1 | I33: =IF($C33="","",IFERROR(INDEX(DB_Rate,MATCH($C33,DB_Key,0)),"")) | K33: =IF($C33="","",IF(ISNUMBER($J33),$J33,IF(ISNUMBER($I33),$I33,""))) | L33: 0 | M33: =IF(AND($B33="Yes",$C33<>"",ISNUMBER($K33)),IF($F33="One-Time",$G33*$K33*(1-$L33),$G33*$H33*$K33*(1-$L33)),0) -> 0
L35: Accessories Subtotal | M35: =SUM(M6:M33) -> 0

Sheet Quote Summary
B2: QUOTE SUMMARY (INTERNAL)
B3: Consolidated view of configured equipment and add-ons with totals.
B5: =IF(Quote_Number="","Quote #: (enter on Start Quote)","Quote #: "&Quote_Number) -> Quote #: (enter on Start Quote)
B6: =IF(Cust_Company="","Customer: -","Customer: "&Cust_Company) -> Customer: -
B8: Configuration | C8: Code | D8: Qty | E8: Unit Daily | F8: Extended
B9: =IF(ISNUMBER(MATCH(1,CfgRank,0)),INDEX('Guided Configurator'!$P:$P,INDEX(CfgRankRow,MATCH(1,CfgRank,0))),"") | C9: =IF(ISNUMBER(MATCH(1,CfgRank,0)),INDEX('Guided Configurator'!$O:$O,INDEX(CfgRankRow,MATCH(1,CfgRank,0))),"") | D9: =IF(ISNUMBER(MATCH(1,CfgRank,0)),INDEX('Guided Configurator'!$H:$H,INDEX(CfgRankRow,MATCH(1,CfgRank,0))),"") | E9: =IF(ISNUMBER(MATCH(1,CfgRank,0)),INDEX('Guided Configurator'!$M:$M,INDEX(CfgRankRow,MATCH(1,CfgRank,0))),"") | F9: =IF(ISNUMBER(MATCH(1,CfgRank,0)),INDEX('Guided Configurator'!$N:$N,INDEX(CfgRankRow,MATCH(1,CfgRank,0))),"")
B10: =IF(ISNUMBER(MATCH(2,CfgRank,0)),INDEX('Guided Configurator'!$P:$P,INDEX(CfgRankRow,MATCH(2,CfgRank,0))),"") | C10: =IF(ISNUMBER(MATCH(2,CfgRank,0)),INDEX('Guided Configurator'!$O:$O,INDEX(CfgRankRow,MATCH(2,CfgRank,0))),"") | D10: =IF(ISNUMBER(MATCH(2,CfgRank,0)),INDEX('Guided Configurator'!$H:$H,INDEX(CfgRankRow,MATCH(2,CfgRank,0))),"") | E10: =IF(ISNUMBER(MATCH(2,CfgRank,0)),INDEX('Guided Configurator'!$M:$M,INDEX(CfgRankRow,MATCH(2,CfgRank,0))),"") | F10: =IF(ISNUMBER(MATCH(2,CfgRank,0)),INDEX('Guided Configurator'!$N:$N,INDEX(CfgRankRow,MATCH(2,CfgRank,0))),"")
B11: =IF(ISNUMBER(MATCH(3,CfgRank,0)),INDEX('Guided Configurator'!$P:$P,INDEX(CfgRankRow,MATCH(3,CfgRank,0))),"") | C11: =IF(ISNUMBER(MATCH(3,CfgRank,0)),INDEX('Guided Configurator'!$O:$O,INDEX(CfgRankRow,MATCH(3,CfgRank,0))),"") | D11: =IF(ISNUMBER(MATCH(3,CfgRank,0)),INDEX('Guided Configurator'!$H:$H,INDEX(CfgRankRow,MATCH(3,CfgRank,0))),"") | E11: =IF(ISNUMBER(MATCH(3,CfgRank,0)),INDEX('Guided Configurator'!$M:$M,INDEX(CfgRankRow,MATCH(3,CfgRank,0))),"") | F11: =IF(ISNUMBER(MATCH(3,CfgRank,0)),INDEX('Guided Configurator'!$N:$N,INDEX(CfgRankRow,MATCH(3,CfgRank,0))),"")
B12: =IF(ISNUMBER(MATCH(4,CfgRank,0)),INDEX('Guided Configurator'!$P:$P,INDEX(CfgRankRow,MATCH(4,CfgRank,0))),"") | C12: =IF(ISNUMBER(MATCH(4,CfgRank,0)),INDEX('Guided Configurator'!$O:$O,INDEX(CfgRankRow,MATCH(4,CfgRank,0))),"") | D12: =IF(ISNUMBER(MATCH(4,CfgRank,0)),INDEX('Guided Configurator'!$H:$H,INDEX(CfgRankRow,MATCH(4,CfgRank,0))),"") | E12: =IF(ISNUMBER(MATCH(4,CfgRank,0)),INDEX('Guided Configurator'!$M:$M,INDEX(CfgRankRow,MATCH(4,CfgRank,0))),"") | F12: =IF(ISNUMBER(MATCH(4,CfgRank,0)),INDEX('Guided Configurator'!$N:$N,INDEX(CfgRankRow,MATCH(4,CfgRank,0))),"")
B13: =IF(ISNUMBER(MATCH(5,CfgRank,0)),INDEX('Guided Configurator'!$P:$P,INDEX(CfgRankRow,MATCH(5,CfgRank,0))),"") | C13: =IF(ISNUMBER(MATCH(5,CfgRank,0)),INDEX('Guided Configurator'!$O:$O,INDEX(CfgRankRow,MATCH(5,CfgRank,0))),"") | D13: =IF(ISNUMBER(MATCH(5,CfgRank,0)),INDEX('Guided Configurator'!$H:$H,INDEX(CfgRankRow,MATCH(5,CfgRank,0))),"") | E13: =IF(ISNUMBER(MATCH(5,CfgRank,0)),INDEX('Guided Configurator'!$M:$M,INDEX(CfgRankRow,MATCH(5,CfgRank,0))),"") | F13: =IF(ISNUMBER(MATCH(5,CfgRank,0)),INDEX('Guided Configurator'!$N:$N,INDEX(CfgRankRow,MATCH(5,CfgRank,0))),"")
B14: =IF(ISNUMBER(MATCH(6,CfgRank,0)),INDEX('Guided Configurator'!$P:$P,INDEX(CfgRankRow,MATCH(6,CfgRank,0))),"") | C14: =IF(ISNUMBER(MATCH(6,CfgRank,0)),INDEX('Guided Configurator'!$O:$O,INDEX(CfgRankRow,MATCH(6,CfgRank,0))),"") | D14: =IF(ISNUMBER(MATCH(6,CfgRank,0)),INDEX('Guided Configurator'!$H:$H,INDEX(CfgRankRow,MATCH(6,CfgRank,0))),"") | E14: =IF(ISNUMBER(MATCH(6,CfgRank,0)),INDEX('Guided Configurator'!$M:$M,INDEX(CfgRankRow,MATCH(6,CfgRank,0))),"") | F14: =IF(ISNUMBER(MATCH(6,CfgRank,0)),INDEX('Guided Configurator'!$N:$N,INDEX(CfgRankRow,MATCH(6,CfgRank,0))),"")
B15: =IF(ISNUMBER(MATCH(7,CfgRank,0)),INDEX('Guided Configurator'!$P:$P,INDEX(CfgRankRow,MATCH(7,CfgRank,0))),"") | C15: =IF(ISNUMBER(MATCH(7,CfgRank,0)),INDEX('Guided Configurator'!$O:$O,INDEX(CfgRankRow,MATCH(7,CfgRank,0))),"") | D15: =IF(ISNUMBER(MATCH(7,CfgRank,0)),INDEX('Guided Configurator'!$H:$H,INDEX(CfgRankRow,MATCH(7,CfgRank,0))),"") | E15: =IF(ISNUMBER(MATCH(7,CfgRank,0)),INDEX('Guided Configurator'!$M:$M,INDEX(CfgRankRow,MATCH(7,CfgRank,0))),"") | F15: =IF(ISNUMBER(MATCH(7,CfgRank,0)),INDEX('Guided Configurator'!$N:$N,INDEX(CfgRankRow,MATCH(7,CfgRank,0))),"")
B16: =IF(ISNUMBER(MATCH(8,CfgRank,0)),INDEX('Guided Configurator'!$P:$P,INDEX(CfgRankRow,MATCH(8,CfgRank,0))),"") | C16: =IF(ISNUMBER(MATCH(8,CfgRank,0)),INDEX('Guided Configurator'!$O:$O,INDEX(CfgRankRow,MATCH(8,CfgRank,0))),"") | D16: =IF(ISNUMBER(MATCH(8,CfgRank,0)),INDEX('Guided Configurator'!$H:$H,INDEX(CfgRankRow,MATCH(8,CfgRank,0))),"") | E16: =IF(ISNUMBER(MATCH(8,CfgRank,0)),INDEX('Guided Configurator'!$M:$M,INDEX(CfgRankRow,MATCH(8,CfgRank,0))),"") | F16: =IF(ISNUMBER(MATCH(8,CfgRank,0)),INDEX('Guided Configurator'!$N:$N,INDEX(CfgRankRow,MATCH(8,CfgRank,0))),"")
B17: =IF(ISNUMBER(MATCH(9,CfgRank,0)),INDEX('Guided Configurator'!$P:$P,INDEX(CfgRankRow,MATCH(9,CfgRank,0))),"") | C17: =IF(ISNUMBER(MATCH(9,CfgRank,0)),INDEX('Guided Configurator'!$O:$O,INDEX(CfgRankRow,MATCH(9,CfgRank,0))),"") | D17: =IF(ISNUMBER(MATCH(9,CfgRank,0)),INDEX('Guided Configurator'!$H:$H,INDEX(CfgRankRow,MATCH(9,CfgRank,0))),"") | E17: =IF(ISNUMBER(MATCH(9,CfgRank,0)),INDEX('Guided Configurator'!$M:$M,INDEX(CfgRankRow,MATCH(9,CfgRank,0))),"") | F17: =IF(ISNUMBER(MATCH(9,CfgRank,0)),INDEX('Guided Configurator'!$N:$N,INDEX(CfgRankRow,MATCH(9,CfgRank,0))),"")
B18: =IF(ISNUMBER(MATCH(10,CfgRank,0)),INDEX('Guided Configurator'!$P:$P,INDEX(CfgRankRow,MATCH(10,CfgRank,0))),"") | C18: =IF(ISNUMBER(MATCH(10,CfgRank,0)),INDEX('Guided Configurator'!$O:$O,INDEX(CfgRankRow,MATCH(10,CfgRank,0))),"") | D18: =IF(ISNUMBER(MATCH(10,CfgRank,0)),INDEX('Guided Configurator'!$H:$H,INDEX(CfgRankRow,MATCH(10,CfgRank,0))),"") | E18: =IF(ISNUMBER(MATCH(10,CfgRank,0)),INDEX('Guided Configurator'!$M:$M,INDEX(CfgRankRow,MATCH(10,CfgRank,0))),"") | F18: =IF(ISNUMBER(MATCH(10,CfgRank,0)),INDEX('Guided Configurator'!$N:$N,INDEX(CfgRankRow,MATCH(10,CfgRank,0))),"")
E19: Configured Equipment Subtotal | F19: =Config_Subtotal -> 0
B21: Accessories & Services | E21: Subtotal | F21: =Acc_Subtotal -> 0
E23: Subtotal | F23: =Quote_Subtotal -> 0
E24: Freight | F24: =Freight -> 0
E25: Miscellaneous | F25: =Misc_Charge -> 0
E26: =CONCATENATE("Tax (",TEXT(Tax_Rate,"0.0%"),")") -> Tax (0.0%) | F26: =ROUND(Quote_Subtotal*Tax_Rate,2) -> 0
D27: GRAND TOTAL | F27: =Quote_GrandTotal -> 0

Sheet Printable Quote
B2: RENTAL QUOTATION
B3: Gas Detection Equipment Rental — 2026 Pricing
B5: Quote Number | C5: =IF(Quote_Number="","",Quote_Number) | F5: Customer | G5: =IF(Cust_Company="","",Cust_Company)
B6: Quote Date | C6: =IF(ISNUMBER(Quote_Date),TEXT(Quote_Date,"mmm d, yyyy"),"") | F6: Contact | G6: =IF(Cust_Contact="","",Cust_Contact)
B7: Valid Through | C7: =IF(ISNUMBER(Valid_Through),TEXT(Valid_Through,"mmm d, yyyy"),"") | F7: Email / Phone | G7: =IF(AND(Cust_Email="",Cust_Phone=""),"",Cust_Email&IF(AND(Cust_Email<>"",Cust_Phone<>"")," | ","")&Cust_Phone)
B8: Salesperson | C8: =IF(Salesperson="","",Salesperson) | F8: Project / Site | G8: =IF(Cust_Project="","",Cust_Project)
B10: =IF(AND(ISNUMBER(Rental_Start),ISNUMBER(Rental_End)),"Rental Period: "&TEXT(Rental_Start,"mmm d, yyyy")&" to "&TEXT(Rental_End,"mmm d, yyyy")&" ("&Default_Days&" days)","")
B12: CONFIGURED EQUIPMENT
B13: Config Code | C13: Configuration | D13: Qty | E13: Days | F13: Unit Daily | G13: Disc | H13: Amount
B14: =IF(ISNUMBER(MATCH(1,CfgRank,0)),INDEX('Guided Configurator'!$O:$O,INDEX(CfgRankRow,MATCH(1,CfgRank,0))),"") | C14: =IF(ISNUMBER(MATCH(1,CfgRank,0)),INDEX('Guided Configurator'!$P:$P,INDEX(CfgRankRow,MATCH(1,CfgRank,0))),"") | D14: =IF(ISNUMBER(MATCH(1,CfgRank,0)),INDEX('Guided Configurator'!$H:$H,INDEX(CfgRankRow,MATCH(1,CfgRank,0))),"") | E14: =IF(ISNUMBER(MATCH(1,CfgRank,0)),INDEX('Guided Configurator'!$I:$I,INDEX(CfgRankRow,MATCH(1,CfgRank,0))),"") | F14: =IF(ISNUMBER(MATCH(1,CfgRank,0)),INDEX('Guided Configurator'!$M:$M,INDEX(CfgRankRow,MATCH(1,CfgRank,0))),"") | G14: =IF(ISNUMBER(MATCH(1,CfgRank,0)),INDEX('Guided Configurator'!$J:$J,INDEX(CfgRankRow,MATCH(1,CfgRank,0))),"") | H14: =IF(ISNUMBER(MATCH(1,CfgRank,0)),INDEX('Guided Configurator'!$N:$N,INDEX(CfgRankRow,MATCH(1,CfgRank,0))),"")
B15: =IF(ISNUMBER(MATCH(2,CfgRank,0)),INDEX('Guided Configurator'!$O:$O,INDEX(CfgRankRow,MATCH(2,CfgRank,0))),"") | C15: =IF(ISNUMBER(MATCH(2,CfgRank,0)),INDEX('Guided Configurator'!$P:$P,INDEX(CfgRankRow,MATCH(2,CfgRank,0))),"") | D15: =IF(ISNUMBER(MATCH(2,CfgRank,0)),INDEX('Guided Configurator'!$H:$H,INDEX(CfgRankRow,MATCH(2,CfgRank,0))),"") | E15: =IF(ISNUMBER(MATCH(2,CfgRank,0)),INDEX('Guided Configurator'!$I:$I,INDEX(CfgRankRow,MATCH(2,CfgRank,0))),"") | F15: =IF(ISNUMBER(MATCH(2,CfgRank,0)),INDEX('Guided Configurator'!$M:$M,INDEX(CfgRankRow,MATCH(2,CfgRank,0))),"") | G15: =IF(ISNUMBER(MATCH(2,CfgRank,0)),INDEX('Guided Configurator'!$J:$J,INDEX(CfgRankRow,MATCH(2,CfgRank,0))),"") | H15: =IF(ISNUMBER(MATCH(2,CfgRank,0)),INDEX('Guided Configurator'!$N:$N,INDEX(CfgRankRow,MATCH(2,CfgRank,0))),"")
B16: =IF(ISNUMBER(MATCH(3,CfgRank,0)),INDEX('Guided Configurator'!$O:$O,INDEX(CfgRankRow,MATCH(3,CfgRank,0))),"") | C16: =IF(ISNUMBER(MATCH(3,CfgRank,0)),INDEX('Guided Configurator'!$P:$P,INDEX(CfgRankRow,MATCH(3,CfgRank,0))),"") | D16: =IF(ISNUMBER(MATCH(3,CfgRank,0)),INDEX('Guided Configurator'!$H:$H,INDEX(CfgRankRow,MATCH(3,CfgRank,0))),"") | E16: =IF(ISNUMBER(MATCH(3,CfgRank,0)),INDEX('Guided Configurator'!$I:$I,INDEX(CfgRankRow,MATCH(3,CfgRank,0))),"") | F16: =IF(ISNUMBER(MATCH(3,CfgRank,0)),INDEX('Guided Configurator'!$M:$M,INDEX(CfgRankRow,MATCH(3,CfgRank,0))),"") | G16: =IF(ISNUMBER(MATCH(3,CfgRank,0)),INDEX('Guided Configurator'!$J:$J,INDEX(CfgRankRow,MATCH(3,CfgRank,0))),"") | H16: =IF(ISNUMBER(MATCH(3,CfgRank,0)),INDEX('Guided Configurator'!$N:$N,INDEX(CfgRankRow,MATCH(3,CfgRank,0))),"")
B17: =IF(ISNUMBER(MATCH(4,CfgRank,0)),INDEX('Guided Configurator'!$O:$O,INDEX(CfgRankRow,MATCH(4,CfgRank,0))),"") | C17: =IF(ISNUMBER(MATCH(4,CfgRank,0)),INDEX('Guided Configurator'!$P:$P,INDEX(CfgRankRow,MATCH(4,CfgRank,0))),"") | D17: =IF(ISNUMBER(MATCH(4,CfgRank,0)),INDEX('Guided Configurator'!$H:$H,INDEX(CfgRankRow,MATCH(4,CfgRank,0))),"") | E17: =IF(ISNUMBER(MATCH(4,CfgRank,0)),INDEX('Guided Configurator'!$I:$I,INDEX(CfgRankRow,MATCH(4,CfgRank,0))),"") | F17: =IF(ISNUMBER(MATCH(4,CfgRank,0)),INDEX('Guided Configurator'!$M:$M,INDEX(CfgRankRow,MATCH(4,CfgRank,0))),"") | G17: =IF(ISNUMBER(MATCH(4,CfgRank,0)),INDEX('Guided Configurator'!$J:$J,INDEX(CfgRankRow,MATCH(4,CfgRank,0))),"") | H17: =IF(ISNUMBER(MATCH(4,CfgRank,0)),INDEX('Guided Configurator'!$N:$N,INDEX(CfgRankRow,MATCH(4,CfgRank,0))),"")
B18: =IF(ISNUMBER(MATCH(5,CfgRank,0)),INDEX('Guided Configurator'!$O:$O,INDEX(CfgRankRow,MATCH(5,CfgRank,0))),"") | C18: =IF(ISNUMBER(MATCH(5,CfgRank,0)),INDEX('Guided Configurator'!$P:$P,INDEX(CfgRankRow,MATCH(5,CfgRank,0))),"") | D18: =IF(ISNUMBER(MATCH(5,CfgRank,0)),INDEX('Guided Configurator'!$H:$H,INDEX(CfgRankRow,MATCH(5,CfgRank,0))),"") | E18: =IF(ISNUMBER(MATCH(5,CfgRank,0)),INDEX('Guided Configurator'!$I:$I,INDEX(CfgRankRow,MATCH(5,CfgRank,0))),"") | F18: =IF(ISNUMBER(MATCH(5,CfgRank,0)),INDEX('Guided Configurator'!$M:$M,INDEX(CfgRankRow,MATCH(5,CfgRank,0))),"") | G18: =IF(ISNUMBER(MATCH(5,CfgRank,0)),INDEX('Guided Configurator'!$J:$J,INDEX(CfgRankRow,MATCH(5,CfgRank,0))),"") | H18: =IF(ISNUMBER(MATCH(5,CfgRank,0)),INDEX('Guided Configurator'!$N:$N,INDEX(CfgRankRow,MATCH(5,CfgRank,0))),"")
B19: =IF(ISNUMBER(MATCH(6,CfgRank,0)),INDEX('Guided Configurator'!$O:$O,INDEX(CfgRankRow,MATCH(6,CfgRank,0))),"") | C19: =IF(ISNUMBER(MATCH(6,CfgRank,0)),INDEX('Guided Configurator'!$P:$P,INDEX(CfgRankRow,MATCH(6,CfgRank,0))),"") | D19: =IF(ISNUMBER(MATCH(6,CfgRank,0)),INDEX('Guided Configurator'!$H:$H,INDEX(CfgRankRow,MATCH(6,CfgRank,0))),"") | E19: =IF(ISNUMBER(MATCH(6,CfgRank,0)),INDEX('Guided Configurator'!$I:$I,INDEX(CfgRankRow,MATCH(6,CfgRank,0))),"") | F19: =IF(ISNUMBER(MATCH(6,CfgRank,0)),INDEX('Guided Configurator'!$M:$M,INDEX(CfgRankRow,MATCH(6,CfgRank,0))),"") | G19: =IF(ISNUMBER(MATCH(6,CfgRank,0)),INDEX('Guided Configurator'!$J:$J,INDEX(CfgRankRow,MATCH(6,CfgRank,0))),"") | H19: =IF(ISNUMBER(MATCH(6,CfgRank,0)),INDEX('Guided Configurator'!$N:$N,INDEX(CfgRankRow,MATCH(6,CfgRank,0))),"")
B20: =IF(ISNUMBER(MATCH(7,CfgRank,0)),INDEX('Guided Configurator'!$O:$O,INDEX(CfgRankRow,MATCH(7,CfgRank,0))),"") | C20: =IF(ISNUMBER(MATCH(7,CfgRank,0)),INDEX('Guided Configurator'!$P:$P,INDEX(CfgRankRow,MATCH(7,CfgRank,0))),"") | D20: =IF(ISNUMBER(MATCH(7,CfgRank,0)),INDEX('Guided Configurator'!$H:$H,INDEX(CfgRankRow,MATCH(7,CfgRank,0))),"") | E20: =IF(ISNUMBER(MATCH(7,CfgRank,0)),INDEX('Guided Configurator'!$I:$I,INDEX(CfgRankRow,MATCH(7,CfgRank,0))),"") | F20: =IF(ISNUMBER(MATCH(7,CfgRank,0)),INDEX('Guided Configurator'!$M:$M,INDEX(CfgRankRow,MATCH(7,CfgRank,0))),"") | G20: =IF(ISNUMBER(MATCH(7,CfgRank,0)),INDEX('Guided Configurator'!$J:$J,INDEX(CfgRankRow,MATCH(7,CfgRank,0))),"") | H20: =IF(ISNUMBER(MATCH(7,CfgRank,0)),INDEX('Guided Configurator'!$N:$N,INDEX(CfgRankRow,MATCH(7,CfgRank,0))),"")
B21: =IF(ISNUMBER(MATCH(8,CfgRank,0)),INDEX('Guided Configurator'!$O:$O,INDEX(CfgRankRow,MATCH(8,CfgRank,0))),"") | C21: =IF(ISNUMBER(MATCH(8,CfgRank,0)),INDEX('Guided Configurator'!$P:$P,INDEX(CfgRankRow,MATCH(8,CfgRank,0))),"") | D21: =IF(ISNUMBER(MATCH(8,CfgRank,0)),INDEX('Guided Configurator'!$H:$H,INDEX(CfgRankRow,MATCH(8,CfgRank,0))),"") | E21: =IF(ISNUMBER(MATCH(8,CfgRank,0)),INDEX('Guided Configurator'!$I:$I,INDEX(CfgRankRow,MATCH(8,CfgRank,0))),"") | F21: =IF(ISNUMBER(MATCH(8,CfgRank,0)),INDEX('Guided Configurator'!$M:$M,INDEX(CfgRankRow,MATCH(8,CfgRank,0))),"") | G21: =IF(ISNUMBER(MATCH(8,CfgRank,0)),INDEX('Guided Configurator'!$J:$J,INDEX(CfgRankRow,MATCH(8,CfgRank,0))),"") | H21: =IF(ISNUMBER(MATCH(8,CfgRank,0)),INDEX('Guided Configurator'!$N:$N,INDEX(CfgRankRow,MATCH(8,CfgRank,0))),"")
B22: =IF(ISNUMBER(MATCH(9,CfgRank,0)),INDEX('Guided Configurator'!$O:$O,INDEX(CfgRankRow,MATCH(9,CfgRank,0))),"") | C22: =IF(ISNUMBER(MATCH(9,CfgRank,0)),INDEX('Guided Configurator'!$P:$P,INDEX(CfgRankRow,MATCH(9,CfgRank,0))),"") | D22: =IF(ISNUMBER(MATCH(9,CfgRank,0)),INDEX('Guided Configurator'!$H:$H,INDEX(CfgRankRow,MATCH(9,CfgRank,0))),"") | E22: =IF(ISNUMBER(MATCH(9,CfgRank,0)),INDEX('Guided Configurator'!$I:$I,INDEX(CfgRankRow,MATCH(9,CfgRank,0))),"") | F22: =IF(ISNUMBER(MATCH(9,CfgRank,0)),INDEX('Guided Configurator'!$M:$M,INDEX(CfgRankRow,MATCH(9,CfgRank,0))),"") | G22: =IF(ISNUMBER(MATCH(9,CfgRank,0)),INDEX('Guided Configurator'!$J:$J,INDEX(CfgRankRow,MATCH(9,CfgRank,0))),"") | H22: =IF(ISNUMBER(MATCH(9,CfgRank,0)),INDEX('Guided Configurator'!$N:$N,INDEX(CfgRankRow,MATCH(9,CfgRank,0))),"")
B23: =IF(ISNUMBER(MATCH(10,CfgRank,0)),INDEX('Guided Configurator'!$O:$O,INDEX(CfgRankRow,MATCH(10,CfgRank,0))),"") | C23: =IF(ISNUMBER(MATCH(10,CfgRank,0)),INDEX('Guided Configurator'!$P:$P,INDEX(CfgRankRow,MATCH(10,CfgRank,0))),"") | D23: =IF(ISNUMBER(MATCH(10,CfgRank,0)),INDEX('Guided Configurator'!$H:$H,INDEX(CfgRankRow,MATCH(10,CfgRank,0))),"") | E23: =IF(ISNUMBER(MATCH(10,CfgRank,0)),INDEX('Guided Configurator'!$I:$I,INDEX(CfgRankRow,MATCH(10,CfgRank,0))),"") | F23: =IF(ISNUMBER(MATCH(10,CfgRank,0)),INDEX('Guided Configurator'!$M:$M,INDEX(CfgRankRow,MATCH(10,CfgRank,0))),"") | G23: =IF(ISNUMBER(MATCH(10,CfgRank,0)),INDEX('Guided Configurator'!$J:$J,INDEX(CfgRankRow,MATCH(10,CfgRank,0))),"") | H23: =IF(ISNUMBER(MATCH(10,CfgRank,0)),INDEX('Guided Configurator'!$N:$N,INDEX(CfgRankRow,MATCH(10,CfgRank,0))),"")
B25: ACCESSORIES & SERVICES
B26: SKU | C26: Description | D26: Qty | E26: Days | F26: Rate | G26: Disc | H26: Amount
B27: =IF(ISNUMBER(MATCH(1,AccRank,0)),INDEX('Accessories & Services'!$C:$C,INDEX(AccRankRow,MATCH(1,AccRank,0))),"") | C27: =IF(ISNUMBER(MATCH(1,AccRank,0)),INDEX('Accessories & Services'!$D:$D,INDEX(AccRankRow,MATCH(1,AccRank,0))),"") | D27: =IF(ISNUMBER(MATCH(1,AccRank,0)),INDEX('Accessories & Services'!$G:$G,INDEX(AccRankRow,MATCH(1,AccRank,0))),"") | E27: =IF(ISNUMBER(MATCH(1,AccRank,0)),IF(INDEX('Accessories & Services'!$F:$F,INDEX(AccRankRow,MATCH(1,AccRank,0)))="One-Time","One-Time",INDEX('Accessories & Services'!$H:$H,INDEX(AccRankRow,MATCH(1,AccRank,0)))),"") | F27: =IF(ISNUMBER(MATCH(1,AccRank,0)),INDEX('Accessories & Services'!$K:$K,INDEX(AccRankRow,MATCH(1,AccRank,0))),"") | G27: =IF(ISNUMBER(MATCH(1,AccRank,0)),INDEX('Accessories & Services'!$L:$L,INDEX(AccRankRow,MATCH(1,AccRank,0))),"") | H27: =IF(ISNUMBER(MATCH(1,AccRank,0)),INDEX('Accessories & Services'!$M:$M,INDEX(AccRankRow,MATCH(1,AccRank,0))),"")
B28: =IF(ISNUMBER(MATCH(2,AccRank,0)),INDEX('Accessories & Services'!$C:$C,INDEX(AccRankRow,MATCH(2,AccRank,0))),"") | C28: =IF(ISNUMBER(MATCH(2,AccRank,0)),INDEX('Accessories & Services'!$D:$D,INDEX(AccRankRow,MATCH(2,AccRank,0))),"") | D28: =IF(ISNUMBER(MATCH(2,AccRank,0)),INDEX('Accessories & Services'!$G:$G,INDEX(AccRankRow,MATCH(2,AccRank,0))),"") | E28: =IF(ISNUMBER(MATCH(2,AccRank,0)),IF(INDEX('Accessories & Services'!$F:$F,INDEX(AccRankRow,MATCH(2,AccRank,0)))="One-Time","One-Time",INDEX('Accessories & Services'!$H:$H,INDEX(AccRankRow,MATCH(2,AccRank,0)))),"") | F28: =IF(ISNUMBER(MATCH(2,AccRank,0)),INDEX('Accessories & Services'!$K:$K,INDEX(AccRankRow,MATCH(2,AccRank,0))),"") | G28: =IF(ISNUMBER(MATCH(2,AccRank,0)),INDEX('Accessories & Services'!$L:$L,INDEX(AccRankRow,MATCH(2,AccRank,0))),"") | H28: =IF(ISNUMBER(MATCH(2,AccRank,0)),INDEX('Accessories & Services'!$M:$M,INDEX(AccRankRow,MATCH(2,AccRank,0))),"")
B29: =IF(ISNUMBER(MATCH(3,AccRank,0)),INDEX('Accessories & Services'!$C:$C,INDEX(AccRankRow,MATCH(3,AccRank,0))),"") | C29: =IF(ISNUMBER(MATCH(3,AccRank,0)),INDEX('Accessories & Services'!$D:$D,INDEX(AccRankRow,MATCH(3,AccRank,0))),"") | D29: =IF(ISNUMBER(MATCH(3,AccRank,0)),INDEX('Accessories & Services'!$G:$G,INDEX(AccRankRow,MATCH(3,AccRank,0))),"") | E29: =IF(ISNUMBER(MATCH(3,AccRank,0)),IF(INDEX('Accessories & Services'!$F:$F,INDEX(AccRankRow,MATCH(3,AccRank,0)))="One-Time","One-Time",INDEX('Accessories & Services'!$H:$H,INDEX(AccRankRow,MATCH(3,AccRank,0)))),"") | F29: =IF(ISNUMBER(MATCH(3,AccRank,0)),INDEX('Accessories & Services'!$K:$K,INDEX(AccRankRow,MATCH(3,AccRank,0))),"") | G29: =IF(ISNUMBER(MATCH(3,AccRank,0)),INDEX('Accessories & Services'!$L:$L,INDEX(AccRankRow,MATCH(3,AccRank,0))),"") | H29: =IF(ISNUMBER(MATCH(3,AccRank,0)),INDEX('Accessories & Services'!$M:$M,INDEX(AccRankRow,MATCH(3,AccRank,0))),"")
B30: =IF(ISNUMBER(MATCH(4,AccRank,0)),INDEX('Accessories & Services'!$C:$C,INDEX(AccRankRow,MATCH(4,AccRank,0))),"") | C30: =IF(ISNUMBER(MATCH(4,AccRank,0)),INDEX('Accessories & Services'!$D:$D,INDEX(AccRankRow,MATCH(4,AccRank,0))),"") | D30: =IF(ISNUMBER(MATCH(4,AccRank,0)),INDEX('Accessories & Services'!$G:$G,INDEX(AccRankRow,MATCH(4,AccRank,0))),"") | E30: =IF(ISNUMBER(MATCH(4,AccRank,0)),IF(INDEX('Accessories & Services'!$F:$F,INDEX(AccRankRow,MATCH(4,AccRank,0)))="One-Time","One-Time",INDEX('Accessories & Services'!$H:$H,INDEX(AccRankRow,MATCH(4,AccRank,0)))),"") | F30: =IF(ISNUMBER(MATCH(4,AccRank,0)),INDEX('Accessories & Services'!$K:$K,INDEX(AccRankRow,MATCH(4,AccRank,0))),"") | G30: =IF(ISNUMBER(MATCH(4,AccRank,0)),INDEX('Accessories & Services'!$L:$L,INDEX(AccRankRow,MATCH(4,AccRank,0))),"") | H30: =IF(ISNUMBER(MATCH(4,AccRank,0)),INDEX('Accessories & Services'!$M:$M,INDEX(AccRankRow,MATCH(4,AccRank,0))),"")
B31: =IF(ISNUMBER(MATCH(5,AccRank,0)),INDEX('Accessories & Services'!$C:$C,INDEX(AccRankRow,MATCH(5,AccRank,0))),"") | C31: =IF(ISNUMBER(MATCH(5,AccRank,0)),INDEX('Accessories & Services'!$D:$D,INDEX(AccRankRow,MATCH(5,AccRank,0))),"") | D31: =IF(ISNUMBER(MATCH(5,AccRank,0)),INDEX('Accessories & Services'!$G:$G,INDEX(AccRankRow,MATCH(5,AccRank,0))),"") | E31: =IF(ISNUMBER(MATCH(5,AccRank,0)),IF(INDEX('Accessories & Services'!$F:$F,INDEX(AccRankRow,MATCH(5,AccRank,0)))="One-Time","One-Time",INDEX('Accessories & Services'!$H:$H,INDEX(AccRankRow,MATCH(5,AccRank,0)))),"") | F31: =IF(ISNUMBER(MATCH(5,AccRank,0)),INDEX('Accessories & Services'!$K:$K,INDEX(AccRankRow,MATCH(5,AccRank,0))),"") | G31: =IF(ISNUMBER(MATCH(5,AccRank,0)),INDEX('Accessories & Services'!$L:$L,INDEX(AccRankRow,MATCH(5,AccRank,0))),"") | H31: =IF(ISNUMBER(MATCH(5,AccRank,0)),INDEX('Accessories & Services'!$M:$M,INDEX(AccRankRow,MATCH(5,AccRank,0))),"")
